2024-04-21 16:18:22,070 [INFO] USER:Yuriy.Shevchenko processor.py:143:_prepare_bucket_view LOG: Viewing complement, URIBucketView, has been found, setting up the raw data.
2024-04-21 16:18:22,896 [INFO] USER:Yuriy.Shevchenko project_state.py:117:get_remote LOG: Unsafely loaded project state file from S3 bucket. The retrieved object has type: dict
2024-04-21 16:18:22,896 [INFO] USER:Yuriy.Shevchenko project_state.py:122:get_remote LOG: Made ProjectState object from the dict loaded from S3 bucket
2024-04-21 16:18:23,504 [INFO] USER:Yuriy.Shevchenko sync_processor.py:53:sync_project_state LOG: Project state file has been successfully synced
2024-04-21 16:18:23,506 [INFO] USER:Yuriy.Shevchenko helper.py:240:resolve_default_value LOG: Resolved value of deploy_name: task03
2024-04-21 16:18:23,887 [INFO] USER:Yuriy.Shevchenko project_state.py:117:get_remote LOG: Unsafely loaded project state file from S3 bucket. The retrieved object has type: dict
2024-04-21 16:18:23,887 [INFO] USER:Yuriy.Shevchenko project_state.py:122:get_remote LOG: Made ProjectState object from the dict loaded from S3 bucket
2024-04-21 16:18:24,477 [INFO] USER:Yuriy.Shevchenko sync_processor.py:53:sync_project_state LOG: Project state file has been successfully synced
2024-04-21 16:18:24,478 [INFO] USER:Yuriy.Shevchenko helper.py:240:resolve_default_value LOG: Resolved value of bundle_name: task03_240421.161609
2024-04-21 16:18:24,873 [INFO] USER:Yuriy.Shevchenko project_state.py:117:get_remote LOG: Unsafely loaded project state file from S3 bucket. The retrieved object has type: dict
2024-04-21 16:18:24,874 [INFO] USER:Yuriy.Shevchenko project_state.py:122:get_remote LOG: Made ProjectState object from the dict loaded from S3 bucket
2024-04-21 16:18:25,444 [INFO] USER:Yuriy.Shevchenko sync_processor.py:53:sync_project_state LOG: Project state file has been successfully synced
2024-04-21 16:18:25,926 [INFO] USER:Yuriy.Shevchenko project_state.py:117:get_remote LOG: Unsafely loaded project state file from S3 bucket. The retrieved object has type: dict
2024-04-21 16:18:25,927 [INFO] USER:Yuriy.Shevchenko project_state.py:122:get_remote LOG: Made ProjectState object from the dict loaded from S3 bucket
2024-04-21 16:18:26,494 [INFO] USER:Yuriy.Shevchenko sync_processor.py:53:sync_project_state LOG: Project state file has been successfully synced
2024-04-21 16:18:26,846 [ERROR] USER:Yuriy.Shevchenko helper.py:84:wrapper LOG: An error occurred. See details in the log file
2024-04-21 16:18:26,847 [ERROR] USER:Yuriy.Shevchenko helper.py:85:wrapper LOG: Error occurred: Deployment output file not found. It might be because the previous deployment failed. If this is the case deployment can be continued by using the command  'syndicate deploy --continue_deploy' or failed deployed resources can be removed with the command 'syndicate clean --rollback'
Traceback (most recent call last):
  File "C:\Users\yuriy.shevchenko\AppData\Local\Programs\Python\Python311\Lib\site-packages\syndicate\core\build\bundle_processor.py", line 140, in load_latest_deploy_output
    return load_deploy_output(bundle_name, deploy_name)
           ^^^^^^^^^^^^^^^^^^^^^^^^^^^^^^^^^^^^^^^^^^^^
  File "C:\Users\yuriy.shevchenko\AppData\Local\Programs\Python\Python311\Lib\site-packages\syndicate\core\build\bundle_processor.py", line 111, in load_deploy_output
    raise AssertionError('Deploy name {0} does not exist.'
AssertionError: Deploy name task03 does not exist. Cannot find output file.

During handling of the above exception, another exception occurred:

Traceback (most recent call last):
  File "C:\Users\yuriy.shevchenko\AppData\Local\Programs\Python\Python311\Lib\site-packages\syndicate\core\helper.py", line 82, in wrapper
    return handler_func(*args, **kwargs)
           ^^^^^^^^^^^^^^^^^^^^^^^^^^^^^
  File "C:\Users\yuriy.shevchenko\AppData\Local\Programs\Python\Python311\Lib\site-packages\syndicate\core\build\deployment_processor.py", line 298, in create_deployment_resources
    latest_deploy_output = load_latest_deploy_output()
                           ^^^^^^^^^^^^^^^^^^^^^^^^^^^
  File "C:\Users\yuriy.shevchenko\AppData\Local\Programs\Python\Python311\Lib\site-packages\syndicate\core\build\bundle_processor.py", line 143, in load_latest_deploy_output
    raise AssertionError(
AssertionError: Deployment output file not found. It might be because the previous deployment failed. If this is the case deployment can be continued by using the command  'syndicate deploy --continue_deploy' or failed deployed resources can be removed with the command 'syndicate clean --rollback'
2024-04-21 16:18:27,342 [INFO] USER:Yuriy.Shevchenko project_state.py:117:get_remote LOG: Unsafely loaded project state file from S3 bucket. The retrieved object has type: dict
2024-04-21 16:18:27,342 [INFO] USER:Yuriy.Shevchenko project_state.py:122:get_remote LOG: Made ProjectState object from the dict loaded from S3 bucket
2024-04-21 16:18:27,929 [INFO] USER:Yuriy.Shevchenko sync_processor.py:53:sync_project_state LOG: Project state file has been successfully synced
2024-04-21 16:21:07,864 [INFO] USER:Yuriy.Shevchenko processor.py:143:_prepare_bucket_view LOG: Viewing complement, URIBucketView, has been found, setting up the raw data.
2024-04-21 16:21:08,659 [INFO] USER:Yuriy.Shevchenko project_state.py:117:get_remote LOG: Unsafely loaded project state file from S3 bucket. The retrieved object has type: dict
2024-04-21 16:21:08,659 [INFO] USER:Yuriy.Shevchenko project_state.py:122:get_remote LOG: Made ProjectState object from the dict loaded from S3 bucket
2024-04-21 16:21:09,269 [INFO] USER:Yuriy.Shevchenko sync_processor.py:53:sync_project_state LOG: Project state file has been successfully synced
2024-04-21 16:21:09,271 [INFO] USER:Yuriy.Shevchenko helper.py:240:resolve_default_value LOG: Resolved value of deploy_name: task03
2024-04-21 16:21:09,633 [INFO] USER:Yuriy.Shevchenko project_state.py:117:get_remote LOG: Unsafely loaded project state file from S3 bucket. The retrieved object has type: dict
2024-04-21 16:21:09,634 [INFO] USER:Yuriy.Shevchenko project_state.py:122:get_remote LOG: Made ProjectState object from the dict loaded from S3 bucket
2024-04-21 16:21:10,207 [INFO] USER:Yuriy.Shevchenko sync_processor.py:53:sync_project_state LOG: Project state file has been successfully synced
2024-04-21 16:21:10,208 [INFO] USER:Yuriy.Shevchenko helper.py:240:resolve_default_value LOG: Resolved value of bundle_name: task03_240421.161609
2024-04-21 16:21:10,548 [INFO] USER:Yuriy.Shevchenko project_state.py:117:get_remote LOG: Unsafely loaded project state file from S3 bucket. The retrieved object has type: dict
2024-04-21 16:21:10,548 [INFO] USER:Yuriy.Shevchenko project_state.py:122:get_remote LOG: Made ProjectState object from the dict loaded from S3 bucket
2024-04-21 16:21:11,129 [INFO] USER:Yuriy.Shevchenko sync_processor.py:53:sync_project_state LOG: Project state file has been successfully synced
2024-04-21 16:21:11,637 [INFO] USER:Yuriy.Shevchenko project_state.py:117:get_remote LOG: Unsafely loaded project state file from S3 bucket. The retrieved object has type: dict
2024-04-21 16:21:11,637 [INFO] USER:Yuriy.Shevchenko project_state.py:122:get_remote LOG: Made ProjectState object from the dict loaded from S3 bucket
2024-04-21 16:21:12,208 [INFO] USER:Yuriy.Shevchenko sync_processor.py:53:sync_project_state LOG: Project state file has been successfully synced
2024-04-21 16:21:12,560 [ERROR] USER:Yuriy.Shevchenko helper.py:84:wrapper LOG: An error occurred. See details in the log file
2024-04-21 16:21:12,561 [ERROR] USER:Yuriy.Shevchenko helper.py:85:wrapper LOG: Error occurred: Deploy name task03 does not exist. Cannot find output file.
Traceback (most recent call last):
  File "C:\Users\yuriy.shevchenko\AppData\Local\Programs\Python\Python311\Lib\site-packages\syndicate\core\helper.py", line 82, in wrapper
    return handler_func(*args, **kwargs)
           ^^^^^^^^^^^^^^^^^^^^^^^^^^^^^
  File "C:\Users\yuriy.shevchenko\AppData\Local\Programs\Python\Python311\Lib\site-packages\syndicate\core\build\deployment_processor.py", line 501, in continue_deployment_resources
    output = load_failed_deploy_output(bundle_name, deploy_name)
             ^^^^^^^^^^^^^^^^^^^^^^^^^^^^^^^^^^^^^^^^^^^^^^^^^^^
  File "C:\Users\yuriy.shevchenko\AppData\Local\Programs\Python\Python311\Lib\site-packages\syndicate\core\build\bundle_processor.py", line 129, in load_failed_deploy_output
    raise AssertionError('Deploy name {0} does not exist.'
AssertionError: Deploy name task03 does not exist. Cannot find output file.
2024-04-21 16:21:13,020 [INFO] USER:Yuriy.Shevchenko project_state.py:117:get_remote LOG: Unsafely loaded project state file from S3 bucket. The retrieved object has type: dict
2024-04-21 16:21:13,020 [INFO] USER:Yuriy.Shevchenko project_state.py:122:get_remote LOG: Made ProjectState object from the dict loaded from S3 bucket
2024-04-21 16:21:13,618 [INFO] USER:Yuriy.Shevchenko sync_processor.py:53:sync_project_state LOG: Project state file has been successfully synced
2024-04-21 16:29:13,967 [INFO] USER:Yuriy.Shevchenko project.py:77:generate_project_structure LOG: Project task04 folder has been successfully created.
2024-04-21 16:29:13,967 [INFO] USER:Yuriy.Shevchenko helper.py:336:timed LOG: Stage project, elapsed time: 0:00:00.412851
2024-04-21 16:32:51,239 [INFO] USER:Yuriy.Shevchenko s3_resource.py:40:validate_bucket_name LOG: Starting validating bucket name 'syndicate-education-platform-custom-sandbox-artifacts-sbox01'
2024-04-21 16:32:51,239 [INFO] USER:Yuriy.Shevchenko s3_resource.py:73:validate_bucket_name LOG: Finished validating bucket name 'syndicate-education-platform-custom-sandbox-artifacts-sbox01'
2024-04-21 16:32:51,972 [WARNING] USER:Yuriy.Shevchenko generator.py:76:generate_configuration_files LOG: The config_path property is not specified. The working directory is used
2024-04-21 16:32:51,973 [WARNING] USER:Yuriy.Shevchenko generator.py:93:generate_configuration_files LOG: The "project_path" property is not specified. The working directory will be used as a project path. To change the path, edit the syndicate.yml by path F:\AWS\Tasks\AWS_Serverless_tasks\task04\.syndicate-config-dev
2024-04-21 16:32:52,009 [INFO] USER:Yuriy.Shevchenko generator.py:155:generate_configuration_files LOG: Syndicate initialization has been completed. 
Set SDCT_CONF:
Unix: export SDCT_CONF="F:\AWS\Tasks\AWS_Serverless_tasks\task04\.syndicate-config-dev"
Windows: setx SDCT_CONF F:\AWS\Tasks\AWS_Serverless_tasks\task04\.syndicate-config-dev
2024-04-21 16:32:52,015 [INFO] USER:Yuriy.Shevchenko helper.py:336:timed LOG: Stage config, elapsed time: 0:00:00.775542
2024-04-21 16:33:17,587 [INFO] USER:Yuriy.Shevchenko processor.py:143:_prepare_bucket_view LOG: Viewing complement, URIBucketView, has been found, setting up the raw data.
2024-04-21 16:33:17,950 [INFO] USER:Yuriy.Shevchenko bundle_processor.py:207:create_bundles_bucket LOG: Bundles bucket syndicate-education-platform-custom-sandbox-artifacts-sbox01 already exists
2024-04-21 16:33:17,951 [INFO] USER:Yuriy.Shevchenko helper.py:336:timed LOG: Stage create_deploy_target_bucket, elapsed time: 0:00:00.364484
2024-04-21 16:33:34,191 [INFO] USER:Yuriy.Shevchenko helper.py:588:check_lambda_name LOG: Validating lambda name: 'hello_world'
2024-04-21 16:33:34,191 [INFO] USER:Yuriy.Shevchenko helper.py:603:check_lambda_name LOG: Lambda name: 'hello_world' passed the validation
2024-04-21 16:33:34,193 [INFO] USER:Yuriy.Shevchenko project.py:90:_generate_java_project_hierarchy LOG: Generating pom inside F:\AWS\Tasks\AWS_Serverless_tasks\task04
2024-04-21 16:33:34,193 [INFO] USER:Yuriy.Shevchenko project.py:95:_generate_java_project_hierarchy LOG: Pom file was generated by path: F:\AWS\Tasks\AWS_Serverless_tasks\task04\pom.xml
2024-04-21 16:33:34,243 [INFO] USER:Yuriy.Shevchenko lambda_function.py:319:_generate_java_lambdas LOG: Lambda hello_world created
2024-04-21 16:33:34,243 [INFO] USER:Yuriy.Shevchenko lambda_function.py:146:generate_lambda_function LOG: Lambda hello_world has been successfully added to the project.
2024-04-21 16:33:34,244 [INFO] USER:Yuriy.Shevchenko helper.py:336:timed LOG: Stage lambda_function, elapsed time: 0:00:00.052983
2024-04-21 16:39:33,362 [INFO] USER:Yuriy.Shevchenko helper.py:588:check_lambda_name LOG: Validating lambda name: 'sqs_handler'
2024-04-21 16:39:33,362 [INFO] USER:Yuriy.Shevchenko helper.py:603:check_lambda_name LOG: Lambda name: 'sqs_handler' passed the validation
2024-04-21 16:39:33,364 [INFO] USER:Yuriy.Shevchenko project.py:97:_generate_java_project_hierarchy LOG: Pom file inside F:\AWS\Tasks\AWS_Serverless_tasks\task04 already exists
2024-04-21 16:39:33,366 [INFO] USER:Yuriy.Shevchenko lambda_function.py:319:_generate_java_lambdas LOG: Lambda sqs_handler created
2024-04-21 16:39:33,368 [INFO] USER:Yuriy.Shevchenko lambda_function.py:146:generate_lambda_function LOG: Lambda sqs_handler has been successfully added to the project.
2024-04-21 16:39:33,368 [INFO] USER:Yuriy.Shevchenko helper.py:336:timed LOG: Stage lambda_function, elapsed time: 0:00:00.006001
